[2024-06-28T13:52:01.929+0000] {local_task_job_runner.py:120} INFO - ::group::Pre task execution logs
[2024-06-28T13:52:01.963+0000] {taskinstance.py:2076} INFO - Dependencies all met for dep_context=non-requeueable deps ti=<TaskInstance: my_sample_dag.task_from_script1 scheduled__2023-08-02T00:05:00+00:00 [queued]>
[2024-06-28T13:52:01.977+0000] {taskinstance.py:2076} INFO - Dependencies all met for dep_context=requeueable deps ti=<TaskInstance: my_sample_dag.task_from_script1 scheduled__2023-08-02T00:05:00+00:00 [queued]>
[2024-06-28T13:52:01.980+0000] {taskinstance.py:2306} INFO - Starting attempt 2 of 2
[2024-06-28T13:52:02.004+0000] {taskinstance.py:2330} INFO - Executing <Task(PythonOperator): task_from_script1> on 2023-08-02 00:05:00+00:00
[2024-06-28T13:52:02.016+0000] {warnings.py:112} WARNING - /home/***/.local/lib/python3.12/site-packages/***/task/task_runner/standard_task_runner.py:61: DeprecationWarning: This process (pid=485) is multi-threaded, use of fork() may lead to deadlocks in the child.
  pid = os.fork()

[2024-06-28T13:52:02.019+0000] {standard_task_runner.py:90} INFO - Running: ['***', 'tasks', 'run', 'my_sample_dag', 'task_from_script1', 'scheduled__2023-08-02T00:05:00+00:00', '--job-id', '1738', '--raw', '--subdir', 'DAGS_FOLDER/my_dag.py', '--cfg-path', '/tmp/tmp3jh9wz5h']
[2024-06-28T13:52:02.021+0000] {standard_task_runner.py:63} INFO - Started process 512 to run task
[2024-06-28T13:52:02.021+0000] {standard_task_runner.py:91} INFO - Job 1738: Subtask task_from_script1
[2024-06-28T13:52:02.103+0000] {task_command.py:426} INFO - Running <TaskInstance: my_sample_dag.task_from_script1 scheduled__2023-08-02T00:05:00+00:00 [running]> on host 81089ac3a69d
[2024-06-28T13:52:02.257+0000] {taskinstance.py:2648} INFO - Exporting env vars: AIRFLOW_CTX_DAG_OWNER='***' AIRFLOW_CTX_DAG_ID='my_sample_dag' AIRFLOW_CTX_TASK_ID='task_from_script1' AIRFLOW_CTX_EXECUTION_DATE='2023-08-02T00:05:00+00:00' AIRFLOW_CTX_TRY_NUMBER='2' AIRFLOW_CTX_DAG_RUN_ID='scheduled__2023-08-02T00:05:00+00:00'
[2024-06-28T13:52:02.259+0000] {taskinstance.py:430} INFO - ::endgroup::
[2024-06-28T13:52:02.407+0000] {taskinstance.py:441} INFO - ::group::Post task execution logs
[2024-06-28T13:52:02.408+0000] {taskinstance.py:2905} ERROR - Task failed with exception
Traceback (most recent call last):
  File "/home/airflow/.local/lib/python3.12/site-packages/requests/models.py", line 971, in json
    return complexjson.loads(self.text, **kwargs)
           ^^^^^^^^^^^^^^^^^^^^^^^^^^^^^^^^^^^^^^
  File "/usr/local/lib/python3.12/json/__init__.py", line 346, in loads
    return _default_decoder.decode(s)
           ^^^^^^^^^^^^^^^^^^^^^^^^^^
  File "/usr/local/lib/python3.12/json/decoder.py", line 337, in decode
    obj, end = self.raw_decode(s, idx=_w(s, 0).end())
               ^^^^^^^^^^^^^^^^^^^^^^^^^^^^^^^^^^^^^^
  File "/usr/local/lib/python3.12/json/decoder.py", line 355, in raw_decode
    raise JSONDecodeError("Expecting value", s, err.value) from None
json.decoder.JSONDecodeError: Expecting value: line 1 column 1 (char 0)

During handling of the above exception, another exception occurred:

Traceback (most recent call last):
  File "/home/airflow/.local/lib/python3.12/site-packages/airflow/models/taskinstance.py", line 465, in _execute_task
    result = _execute_callable(context=context, **execute_callable_kwargs)
             ^^^^^^^^^^^^^^^^^^^^^^^^^^^^^^^^^^^^^^^^^^^^^^^^^^^^^^^^^^^^^
  File "/home/airflow/.local/lib/python3.12/site-packages/airflow/models/taskinstance.py", line 432, in _execute_callable
    return execute_callable(context=context, **execute_callable_kwargs)
           ^^^^^^^^^^^^^^^^^^^^^^^^^^^^^^^^^^^^^^^^^^^^^^^^^^^^^^^^^^^^
  File "/home/airflow/.local/lib/python3.12/site-packages/airflow/models/baseoperator.py", line 401, in wrapper
    return func(self, *args, **kwargs)
           ^^^^^^^^^^^^^^^^^^^^^^^^^^^
  File "/home/airflow/.local/lib/python3.12/site-packages/airflow/operators/python.py", line 235, in execute
    return_value = self.execute_callable()
                   ^^^^^^^^^^^^^^^^^^^^^^^
  File "/home/airflow/.local/lib/python3.12/site-packages/airflow/operators/python.py", line 252, in execute_callable
    return self.python_callable(*self.op_args, **self.op_kwargs)
           ^^^^^^^^^^^^^^^^^^^^^^^^^^^^^^^^^^^^^^^^^^^^^^^^^^^^^
  File "/opt/airflow/dags/script1.py", line 11, in function_from_script1
    data = response.json()
           ^^^^^^^^^^^^^^^
  File "/home/airflow/.local/lib/python3.12/site-packages/requests/models.py", line 975, in json
    raise RequestsJSONDecodeError(e.msg, e.doc, e.pos)
requests.exceptions.JSONDecodeError: Expecting value: line 1 column 1 (char 0)
[2024-06-28T13:52:02.426+0000] {taskinstance.py:1206} INFO - Marking task as FAILED. dag_id=my_sample_dag, task_id=task_from_script1, run_id=scheduled__2023-08-02T00:05:00+00:00, execution_date=20230802T000500, start_date=20240628T135201, end_date=20240628T135202
[2024-06-28T13:52:02.448+0000] {standard_task_runner.py:110} ERROR - Failed to execute job 1738 for task task_from_script1 (Expecting value: line 1 column 1 (char 0); 512)
[2024-06-28T13:52:02.490+0000] {local_task_job_runner.py:240} INFO - Task exited with return code 1
[2024-06-28T13:52:02.520+0000] {taskinstance.py:3503} INFO - 0 downstream tasks scheduled from follow-on schedule check
[2024-06-28T13:52:02.527+0000] {local_task_job_runner.py:222} INFO - ::endgroup::
