[2024-06-28T13:47:23.509+0000] {local_task_job_runner.py:120} INFO - ::group::Pre task execution logs
[2024-06-28T13:47:23.551+0000] {taskinstance.py:2076} INFO - Dependencies all met for dep_context=non-requeueable deps ti=<TaskInstance: my_sample_dag.task_from_script1 scheduled__2023-08-05T00:05:00+00:00 [queued]>
[2024-06-28T13:47:23.566+0000] {taskinstance.py:2076} INFO - Dependencies all met for dep_context=requeueable deps ti=<TaskInstance: my_sample_dag.task_from_script1 scheduled__2023-08-05T00:05:00+00:00 [queued]>
[2024-06-28T13:47:23.568+0000] {taskinstance.py:2306} INFO - Starting attempt 1 of 2
[2024-06-28T13:47:23.597+0000] {taskinstance.py:2330} INFO - Executing <Task(PythonOperator): task_from_script1> on 2023-08-05 00:05:00+00:00
[2024-06-28T13:47:23.609+0000] {warnings.py:112} WARNING - /home/***/.local/lib/python3.12/site-packages/***/task/task_runner/standard_task_runner.py:61: DeprecationWarning: This process (pid=285) is multi-threaded, use of fork() may lead to deadlocks in the child.
  pid = os.fork()

[2024-06-28T13:47:23.611+0000] {standard_task_runner.py:63} INFO - Started process 313 to run task
[2024-06-28T13:47:23.611+0000] {standard_task_runner.py:90} INFO - Running: ['***', 'tasks', 'run', 'my_sample_dag', 'task_from_script1', 'scheduled__2023-08-05T00:05:00+00:00', '--job-id', '1725', '--raw', '--subdir', 'DAGS_FOLDER/my_dag.py', '--cfg-path', '/tmp/tmprvmkstq5']
[2024-06-28T13:47:23.613+0000] {standard_task_runner.py:91} INFO - Job 1725: Subtask task_from_script1
[2024-06-28T13:47:23.706+0000] {task_command.py:426} INFO - Running <TaskInstance: my_sample_dag.task_from_script1 scheduled__2023-08-05T00:05:00+00:00 [running]> on host 81089ac3a69d
[2024-06-28T13:47:23.861+0000] {taskinstance.py:2648} INFO - Exporting env vars: AIRFLOW_CTX_DAG_OWNER='***' AIRFLOW_CTX_DAG_ID='my_sample_dag' AIRFLOW_CTX_TASK_ID='task_from_script1' AIRFLOW_CTX_EXECUTION_DATE='2023-08-05T00:05:00+00:00' AIRFLOW_CTX_TRY_NUMBER='1' AIRFLOW_CTX_DAG_RUN_ID='scheduled__2023-08-05T00:05:00+00:00'
[2024-06-28T13:47:23.864+0000] {taskinstance.py:430} INFO - ::endgroup::
[2024-06-28T13:47:24.014+0000] {taskinstance.py:441} INFO - ::group::Post task execution logs
[2024-06-28T13:47:24.019+0000] {taskinstance.py:2905} ERROR - Task failed with exception
Traceback (most recent call last):
  File "/home/airflow/.local/lib/python3.12/site-packages/requests/models.py", line 971, in json
    return complexjson.loads(self.text, **kwargs)
           ^^^^^^^^^^^^^^^^^^^^^^^^^^^^^^^^^^^^^^
  File "/usr/local/lib/python3.12/json/__init__.py", line 346, in loads
    return _default_decoder.decode(s)
           ^^^^^^^^^^^^^^^^^^^^^^^^^^
  File "/usr/local/lib/python3.12/json/decoder.py", line 337, in decode
    obj, end = self.raw_decode(s, idx=_w(s, 0).end())
               ^^^^^^^^^^^^^^^^^^^^^^^^^^^^^^^^^^^^^^
  File "/usr/local/lib/python3.12/json/decoder.py", line 355, in raw_decode
    raise JSONDecodeError("Expecting value", s, err.value) from None
json.decoder.JSONDecodeError: Expecting value: line 1 column 1 (char 0)

During handling of the above exception, another exception occurred:

Traceback (most recent call last):
  File "/home/airflow/.local/lib/python3.12/site-packages/airflow/models/taskinstance.py", line 465, in _execute_task
    result = _execute_callable(context=context, **execute_callable_kwargs)
             ^^^^^^^^^^^^^^^^^^^^^^^^^^^^^^^^^^^^^^^^^^^^^^^^^^^^^^^^^^^^^
  File "/home/airflow/.local/lib/python3.12/site-packages/airflow/models/taskinstance.py", line 432, in _execute_callable
    return execute_callable(context=context, **execute_callable_kwargs)
           ^^^^^^^^^^^^^^^^^^^^^^^^^^^^^^^^^^^^^^^^^^^^^^^^^^^^^^^^^^^^
  File "/home/airflow/.local/lib/python3.12/site-packages/airflow/models/baseoperator.py", line 401, in wrapper
    return func(self, *args, **kwargs)
           ^^^^^^^^^^^^^^^^^^^^^^^^^^^
  File "/home/airflow/.local/lib/python3.12/site-packages/airflow/operators/python.py", line 235, in execute
    return_value = self.execute_callable()
                   ^^^^^^^^^^^^^^^^^^^^^^^
  File "/home/airflow/.local/lib/python3.12/site-packages/airflow/operators/python.py", line 252, in execute_callable
    return self.python_callable(*self.op_args, **self.op_kwargs)
           ^^^^^^^^^^^^^^^^^^^^^^^^^^^^^^^^^^^^^^^^^^^^^^^^^^^^^
  File "/opt/airflow/dags/script1.py", line 11, in function_from_script1
    data = response.json()
           ^^^^^^^^^^^^^^^
  File "/home/airflow/.local/lib/python3.12/site-packages/requests/models.py", line 975, in json
    raise RequestsJSONDecodeError(e.msg, e.doc, e.pos)
requests.exceptions.JSONDecodeError: Expecting value: line 1 column 1 (char 0)
[2024-06-28T13:47:24.036+0000] {taskinstance.py:1206} INFO - Marking task as UP_FOR_RETRY. dag_id=my_sample_dag, task_id=task_from_script1, run_id=scheduled__2023-08-05T00:05:00+00:00, execution_date=20230805T000500, start_date=20240628T134723, end_date=20240628T134724
[2024-06-28T13:47:24.057+0000] {standard_task_runner.py:110} ERROR - Failed to execute job 1725 for task task_from_script1 (Expecting value: line 1 column 1 (char 0); 313)
[2024-06-28T13:47:24.083+0000] {local_task_job_runner.py:240} INFO - Task exited with return code 1
[2024-06-28T13:47:24.113+0000] {taskinstance.py:3503} INFO - 0 downstream tasks scheduled from follow-on schedule check
[2024-06-28T13:47:24.116+0000] {local_task_job_runner.py:222} INFO - ::endgroup::
