[2024-06-28T09:05:34.047+0000] {scheduler_job_runner.py:1562} WARNING - Marking task instance <TaskInstance: my_sample_dag.task_from_script1 scheduled__2023-12-07T00:00:00+00:00 [queued]> stuck in queued as failed. If the task instance has available retries, it will be retried.
[2024-06-28T09:05:34.307+0000] {scheduler_job_runner.py:769} ERROR - Executor reports task instance <TaskInstance: my_sample_dag.task_from_script1 scheduled__2023-12-07T00:00:00+00:00 [queued]> finished (failed) although the task says it's queued. (Info: None) Was the task killed externally?
